<?xml version="1.0" ?>
<robot xmlns:xacro="http://wiki.ros.org/xacro">
  <xacro:macro name="axis_q62" params="prefix parent *origin">
    <link name="${prefix}_base_link">
      <inertial>
        <origin xyz="0 0 0" rpy="0 0 0" />
        <mass value="1" />
        <inertia
          ixx="1.0" ixy="0.0" ixz="0.0"
          iyy="1.0" iyz="0.0"
          izz="1.0" />
      </inertial>
    </link>
    <joint name="${prefix}_base_joint" type="fixed">
      <xacro:insert_block name="origin" />
      <parent link="${parent}" />
      <child link="${prefix}_base_link" />
    </joint>

    <link name="${prefix}_body_link">
      <inertial>
        <origin xyz="0 0 0" rpy="0 0 0" />
        <mass value="1" />
        <inertia
          ixx="1.0" ixy="0.0" ixz="0.0"
          iyy="1.0" iyz="0.0"
          izz="1.0" />
      </inertial>
      <visual>
        <geometry>
          <mesh filename="package://axis_description/meshes/axis_q62_base.stl" scale="0.001 0.001 0.001" />
        </geometry>
        <material name="axis_grey">
          <color rgba="0.7 0.7 0.7 1.0" />
        </material>
        <origin xyz="-0.1 -0.17 0" rpy="0 0 0" />
      </visual>
      <collision>
        <geometry>
          <cylinder radius="0.085" length="0.22" />
        </geometry>
        <origin xyz="0 0 0.11" rpy="0 0 0" />
      </collision>
    </link>
    <joint name="${prefix}_pan_joint" type="continuous">
      <axis xyz="0 0 -1" />
      <parent link="${prefix}_base_link" />
      <child link="${prefix}_body_link" />
      <origin xyz="0 0 0" rpy="0 0 0" />
    </joint>
    <gazebo reference="${prefix}_body_link">
      <material>Gazebo/Grey</material>
    </gazebo>

    <link name="${prefix}_head_link">
      <inertial>
        <origin xyz="0 0 0" rpy="0 0 0" />
        <mass value="1" />
        <inertia
          ixx="1.0" ixy="0.0" ixz="0.0"
          iyy="1.0" iyz="0.0"
          izz="1.0" />
      </inertial>
      <visual>
        <geometry>
          <mesh filename="package://axis_description/meshes/axis_q62_top.stl" scale="0.001 0.001 0.001" />
        </geometry>
        <material name="axis_grey">
          <color rgba="0.7 0.7 0.7 1.0" />
        </material>
        <origin xyz="-0.1 -0.165 -0.215" rpy="0 0 0" />
      </visual>
      <collision>
        <geometry>
          <cylinder radius="0.1" length="0.33" />
        </geometry>
        <origin xyz="0 0 0" rpy="1.5707963267948966 0 0" />
      </collision>
    </link>
    <joint name="${prefix}_tilt_joint" type="revolute">
      <limit lower="-1.5707" upper="1.5707" effort="1" velocity="3.14159" />
      <axis xyz="0 -1 0" />
      <parent link="${prefix}_body_link" />
      <child link="${prefix}_head_link" />
      <origin xyz="0 0 0.215" rpy="0 0 0" />
    </joint>
    <gazebo reference="${prefix}_head_link">
      <material>Gazebo/Grey</material>
    </gazebo>

    <!--
      Add the shades & gazebo reference frame
    -->
    <link name="${prefix}_link">
      <visual>
        <geometry>
          <box size="0.03 0.09 0.01" />
        </geometry>
        <origin xyz="-0.01 0 0.05" rpy="0 0 0" />
        <material name="black">
          <color rgba="0 0 0 1" />
        </material>
      </visual>
      <visual>
        <geometry>
          <box size="0.03 0.09 0.01" />
        </geometry>
        <origin xyz="-0.01 0.20 0.05" rpy="0 0 0" />
        <material name="black">
          <color rgba="0 0 0 1" />
        </material>
      </visual>
      <inertial>
        <origin xyz="0 0 0" rpy="0 0 0" />
        <mass value="1" />
        <inertia
          ixx="1.0" ixy="0.0" ixz="0.0"
          iyy="1.0" iyz="0.0"
          izz="1.0" />
      </inertial>
    </link>
    <joint name="${prefix}_camera_joint" type="fixed">
      <parent link="${prefix}_head_link" />
      <child link="${prefix}_link" />
      <origin xyz="0.1 -0.107 0" rpy="0 0 0" />
    </joint>

    <!--
      Simulation support: sensor and joint controller plugins
      Velocity control is limited to the real-world camera's limits
    -->
    <gazebo>
      <plugin filename="libgz-sim-joint-controller-system.so" name="gz::sim::systems::JointController">
        <joint_name>${prefix}_pan_joint</joint_name>
        <cmd_min>-2.61</cmd_min>
        <cmd_max>2.61</cmd_max>
        <topic>$(arg namespace)/sensors/${prefix}/cmd_pan_vel</topic>
      </plugin>
      <plugin filename="libgz-sim-joint-controller-system.so" name="gz::sim::systems::JointController">
        <joint_name>${prefix}_tilt_joint</joint_name>
        <cmd_min>2.61</cmd_min>
        <cmd_max>2.61</cmd_max>
        <topic>$(arg namespace)/sensors/${prefix}/cmd_tilt_vel</topic>
      </plugin>
      <plugin filename="gz-sim-joint-state-publisher-system" name="gz::sim::systems::JointStatePublisher">
        <joint_name>${prefix}_pan_joint</joint_name>
        <topic>$(arg namespace)/sensors/${prefix}/pan_joint_state</topic>
      </plugin>
      <plugin filename="gz-sim-joint-state-publisher-system" name="gz::sim::systems::JointStatePublisher">
        <joint_name>${prefix}_tilt_joint</joint_name>
        <topic>$(arg namespace)/sensors/${prefix}/tilt_joint_state</topic>
      </plugin>
    </gazebo>
    <gazebo reference="${prefix}_link">
      <plugin filename="libgz-sim-sensors-system.so" name="gz::sim::systems::Sensors">
        <render_engine>ogre2</render_engine>
      </plugin>

      <sensor name="${prefix}_camera" type="camera">
        <update_rate>15</update_rate>
        <visualize>true</visualize>
        <always_on>true</always_on>
        <gz_frame_id>${prefix}_link</gz_frame_id>
        <topic>$(arg namespace)/sensors/${prefix}/image</topic>
        <camera>
          <horizontal_fov>1.5184351666666667</horizontal_fov>
          <vertical_fov>1.0122901111111111</vertical_fov>
          <image>
            <width>640</width>
            <height>480</height>
            <format>R8G8B8</format>
          </image>
          <clip>
            <near>0.1</near>
            <far>100</far>
          </clip>
        </camera>
      </sensor>
    </gazebo>
  </xacro:macro>
</robot>
